[ 2023-07-24 20:46:46,611 ] 187 werkzeug - INFO - [31m[1mWARNING: This is a development server. Do not use it in a production deployment. Use a production WSGI server instead.[0m
 * Running on all addresses (0.0.0.0)
 * Running on http://127.0.0.1:5000
 * Running on http://192.168.209.53:5000
[ 2023-07-24 20:46:46,611 ] 187 werkzeug - INFO - [33mPress CTRL+C to quit[0m
[ 2023-07-24 20:48:15,920 ] 187 werkzeug - INFO - 127.0.0.1 - - [24/Jul/2023 20:48:15] "GET / HTTP/1.1" 200 -
[ 2023-07-24 20:48:15,963 ] 187 werkzeug - INFO - 127.0.0.1 - - [24/Jul/2023 20:48:15] "[33mGET /favicon.ico HTTP/1.1[0m" 404 -
[ 2023-07-24 20:49:03,396 ] 187 werkzeug - INFO - 127.0.0.1 - - [24/Jul/2023 20:49:03] "GET /predictdata HTTP/1.1" 200 -
[ 2023-07-24 20:49:20,756 ] 1414 app - ERROR - Exception on /predictdata [POST]
Traceback (most recent call last):
  File "E:\END-END-PROJECTS\ML-End-to-End-Project\src\pipeline\predict_pipeline.py", line 13, in predict
    model_path=os.path.join("artifacts","model.pkl")
               ^^
NameError: name 'os' is not defined

During handling of the above exception, another exception occurred:

Traceback (most recent call last):
  File "C:\Users\Admin\AppData\Local\Packages\PythonSoftwareFoundation.Python.3.11_qbz5n2kfra8p0\LocalCache\local-packages\Python311\site-packages\flask\app.py", line 2190, in wsgi_app
    response = self.full_dispatch_request()
               ^^^^^^^^^^^^^^^^^^^^^^^^^^^^
  File "C:\Users\Admin\AppData\Local\Packages\PythonSoftwareFoundation.Python.3.11_qbz5n2kfra8p0\LocalCache\local-packages\Python311\site-packages\flask\app.py", line 1486, in full_dispatch_request
    rv = self.handle_user_exception(e)
         ^^^^^^^^^^^^^^^^^^^^^^^^^^^^^
  File "C:\Users\Admin\AppData\Local\Packages\PythonSoftwareFoundation.Python.3.11_qbz5n2kfra8p0\LocalCache\local-packages\Python311\site-packages\flask\app.py", line 1484, in full_dispatch_request
    rv = self.dispatch_request()
         ^^^^^^^^^^^^^^^^^^^^^^^
  File "C:\Users\Admin\AppData\Local\Packages\PythonSoftwareFoundation.Python.3.11_qbz5n2kfra8p0\LocalCache\local-packages\Python311\site-packages\flask\app.py", line 1469, in dispatch_request
    return self.ensure_sync(self.view_functions[rule.endpoint])(**view_args)
           ^^^^^^^^^^^^^^^^^^^^^^^^^^^^^^^^^^^^^^^^^^^^^^^^^^^^^^^^^^^^^^^^^
  File "E:\END-END-PROJECTS\ML-End-to-End-Project\app.py", line 39, in predict_datapoint
    results=predict_pipeline.predict(pred_df)
            ^^^^^^^^^^^^^^^^^^^^^^^^^^^^^^^^^
  File "E:\END-END-PROJECTS\ML-End-to-End-Project\src\pipeline\predict_pipeline.py", line 24, in predict
    raise Custom_Exception(e,sys)
src.exception.Custom_Exception: name 'os' is not defined
[ 2023-07-24 20:49:20,761 ] 187 werkzeug - INFO - 127.0.0.1 - - [24/Jul/2023 20:49:20] "[35m[1mPOST /predictdata HTTP/1.1[0m" 500 -
